<mujoco model="kinovagen3_body">
  <body name="base_link" childclass="kinovagen3">
    <inertial pos="-0.000648 -0.000166 0.084487" quat="0.999294 0.00139618 -0.0118387 0.035636" mass="1.697"
      diaginertia="0.00462407 0.00449437 0.00207755"/>
    <geom class="visual" mesh="base_link"/>
    <geom class="collision" mesh="base_link"/>
    <body name="shoulder_link" pos="0 0 0.15643" quat="0 1 0 0">
      <inertial pos="-2.3e-05 -0.010364 -0.07336" quat="0.707051 0.0451246 -0.0453544 0.704263" mass="1.3773"
        diaginertia="0.00488868 0.00457 0.00135132"/>
      <joint name="joint_1"/>
      <geom class="visual" mesh="shoulder_link"/>
      <geom class="collision" mesh="shoulder_link"/>
      <body name="half_arm_1_link" pos="0 0.005375 -0.12838" quat="1 1 0 0">
        <inertial pos="-4.4e-05 -0.09958 -0.013278" quat="0.482348 0.516286 -0.516862 0.483366" mass="1.1636"
          diaginertia="0.0113017 0.011088 0.00102532"/>
        <joint name="joint_2" range="-2.24 2.24"/>
        <geom class="visual" mesh="half_arm_1_link"/>
        <geom class="collision" mesh="half_arm_1_link"/>
        <body name="half_arm_2_link" pos="0 -0.21038 -0.006375" quat="1 -1 0 0">
          <inertial pos="-4.4e-05 -0.006641 -0.117892" quat="0.706144 0.0213722 -0.0209128 0.707437" mass="1.1636"
            diaginertia="0.0111633 0.010932 0.00100671"/>
          <joint name="joint_3"/>
          <geom class="visual" mesh="half_arm_2_link"/>
          <geom class="collision" mesh="half_arm_2_link"/>
          <body name="forearm_link" pos="0 0.006375 -0.21038" quat="1 1 0 0">
            <inertial pos="-1.8e-05 -0.075478 -0.015006" quat="0.483678 0.515961 -0.515859 0.483455" mass="0.9302"
              diaginertia="0.00834839 0.008147 0.000598606"/>
            <joint name="joint_4" range="-2.57 2.57"/>
            <geom class="visual" mesh="forearm_link"/>
            <geom class="collision" mesh="forearm_link"/>
            <body name="spherical_wrist_1_link" pos="0 -0.20843 -0.006375" quat="1 -1 0 0">
              <inertial pos="1e-06 -0.009432 -0.063883" quat="0.703558 0.0707492 -0.0707492 0.703558" mass="0.6781"
                diaginertia="0.00165901 0.001596 0.000346988"/>
              <joint name="joint_5"/>
              <geom class="visual" mesh="spherical_wrist_1_link"/>
              <geom class="collision" mesh="spherical_wrist_1_link"/>
              <body name="spherical_wrist_2_link" pos="0 0.00017505 -0.10593" quat="1 1 0 0">
                <inertial pos="1e-06 -0.045483 -0.00965" quat="0.44426 0.550121 -0.550121 0.44426" mass="0.6781"
                  diaginertia="0.00170087 0.001641 0.00035013"/>
                <joint name="joint_6" range="-2.09 2.09"/>
                <geom class="visual" mesh="spherical_wrist_2_link"/>
                <geom class="collision" mesh="spherical_wrist_2_link"/>
                <body name="bracelet_link" pos="0 -0.10593 -0.00017505" quat="1 -1 0 0">
                  <inertial pos="0.000281 0.011402 -0.029798" quat="0.394358 0.596779 -0.577293 0.393789" mass="0.5"
                    diaginertia="0.000657336 0.000587019 0.000320645"/>
                  <joint name="joint_7"/>
                  <geom class="visual" mesh="bracelet_with_vision_link"/>
                  <geom class="collision" mesh="bracelet_with_vision_link"/>
                  <camera name="hand" pos="0 -0.05639 -0.058475" quat="0 0 0 1" fovy="41.83792730009236"
                    resolution="640 480"/>
                  <site name="force_sensor" pos="0 0 -0.181525" quat="0 1 0 0" group="3"/>
                  <!-- gripper: robotiq_2f85 -->
                  <body name="gripper_base" pos="0 0 -0.06149039" quat="0 -1 1 0" childclass="2f85">
                    <inertial mass="0.777441" pos="0 -2.70394e-05 0.0354675" quat="1 -0.00152849 0 0"
                        diaginertia="0.000260285 0.000225381 0.000152708"/>
                    <geom class="gripper_visual" mesh="gripper_base" material="black"/>
                    <geom class="gripper_collision" mesh="gripper_base"/>
                    <site name="pinch" pos="0 0 0.145" type="sphere" group="5" rgba="0.9 0.9 0.9 1" size="0.005"/>
                    <!-- Right-hand side 4-bar linkage -->
                    <body name="right_driver" pos="0 0.0306011 0.054904">
                      <inertial mass="0.00899563" pos="2.96931e-12 0.0177547 0.00107314" quat="0.681301 0.732003 0 0"
                        diaginertia="1.72352e-06 1.60906e-06 3.22006e-07"/>
                      <joint name="right_driver_joint" class="driver"/>
                      <geom class="gripper_visual" mesh="driver" material="gray"/>
                      <geom class="gripper_collision" mesh="driver"/>
                      <body name="right_coupler" pos="0 0.0315 -0.0041">
                        <inertial mass="0.0140974" pos="0 0.00301209 0.0232175" quat="0.705636 -0.0455904 0.0455904 0.705636"
                          diaginertia="4.16206e-06 3.52216e-06 8.88131e-07"/>
                        <joint name="right_coupler_joint" class="coupler"/>
                        <geom class="gripper_visual" mesh="coupler" material="black"/>
                        <geom class="gripper_collision" mesh="coupler"/>
                      </body>
                    </body>
                    <body name="right_spring_link" pos="0 0.0132 0.0609">
                      <inertial mass="0.0221642" pos="-8.65005e-09 0.0181624 0.0212658" quat="0.663403 -0.244737 0.244737 0.663403"
                        diaginertia="8.96853e-06 6.71733e-06 2.63931e-06"/>
                      <joint name="right_spring_link_joint" class="spring_link"/>
                      <geom class="gripper_visual" mesh="spring_link" material="black"/>
                      <geom class="gripper_collision" mesh="spring_link"/>
                      <body name="right_follower" pos="0 0.055 0.0375">
                        <inertial mass="0.0125222" pos="0 -0.011046 0.0124786" quat="1 0.1664 0 0"
                          diaginertia="2.67415e-06 2.4559e-06 6.02031e-07"/>
                        <joint name="right_follower_joint" class="follower"/>
                        <geom class="gripper_visual" mesh="follower" material="black"/>
                        <geom class="gripper_collision" mesh="follower"/>
                        <body name="right_pad" pos="0 -0.0189 0.01352">
                          <geom class="pad_box1" name="right_pad1"/>
                          <geom class="pad_box2" name="right_pad2"/>
                          <inertial mass="0.0035" pos="0 -0.0025 0.0185" quat="0.707107 0 0 0.707107"
                            diaginertia="4.73958e-07 3.64583e-07 1.23958e-07"/>
                          <geom class="gripper_visual" mesh="pad"/>
                          <body name="right_silicone_pad">
                            <geom class="gripper_visual" mesh="silicone_pad" material="black"/>
                          </body>
                        </body>
                      </body>
                    </body>
                    <!-- Left-hand side 4-bar linkage -->
                    <body name="left_driver" pos="0 -0.0306011 0.054904" quat="0 0 0 1">
                      <inertial mass="0.00899563" pos="0 0.0177547 0.00107314" quat="0.681301 0.732003 0 0"
                        diaginertia="1.72352e-06 1.60906e-06 3.22006e-07"/>
                      <joint name="left_driver_joint" class="driver"/>
                      <geom class="gripper_visual" mesh="driver" material="gray"/>
                      <geom class="gripper_collision" mesh="driver"/>
                      <body name="left_coupler" pos="0 0.0315 -0.0041">
                        <inertial mass="0.0140974" pos="0 0.00301209 0.0232175" quat="0.705636 -0.0455904 0.0455904 0.705636"
                          diaginertia="4.16206e-06 3.52216e-06 8.88131e-07"/>
                        <joint name="left_coupler_joint" class="coupler"/>
                        <geom class="gripper_visual" mesh="coupler" material="black"/>
                        <geom class="gripper_collision" mesh="coupler"/>
                      </body>
                    </body>
                    <body name="left_spring_link" pos="0 -0.0132 0.0609" quat="0 0 0 1">
                      <inertial mass="0.0221642" pos="-8.65005e-09 0.0181624 0.0212658" quat="0.663403 -0.244737 0.244737 0.663403"
                        diaginertia="8.96853e-06 6.71733e-06 2.63931e-06"/>
                      <joint name="left_spring_link_joint" class="spring_link"/>
                      <geom class="gripper_visual" mesh="spring_link" material="black"/>
                      <geom class="gripper_collision" mesh="spring_link"/>
                      <body name="left_follower" pos="0 0.055 0.0375">
                        <inertial mass="0.0125222" pos="0 -0.011046 0.0124786" quat="1 0.1664 0 0"
                          diaginertia="2.67415e-06 2.4559e-06 6.02031e-07"/>
                        <joint name="left_follower_joint" class="follower"/>
                        <geom class="gripper_visual" mesh="follower" material="black"/>
                        <geom class="gripper_collision" mesh="follower"/>
                        <body name="left_pad" pos="0 -0.0189 0.01352">
                          <geom class="pad_box1" name="left_pad1"/>
                          <geom class="pad_box2" name="left_pad2"/>
                          <inertial mass="0.0035" pos="0 -0.0025 0.0185" quat="1 0 0 1"
                            diaginertia="4.73958e-07 3.64583e-07 1.23958e-07"/>
                          <geom class="gripper_visual" mesh="pad"/>
                          <body name="left_silicone_pad">
                            <geom class="gripper_visual" mesh="silicone_pad" material="black"/>
                          </body>
                        </body>
                      </body>
                    </body>
                  </body>
                </body>
              </body>
            </body>
          </body>
        </body>
      </body>
    </body>
  </body>
</mujoco>
