<mujoco name="crx5ia_body">
  <body name="base_link" pos="0 0 0" childclass="crx5ia">
    <inertial pos="-0.02329 -0.00113 0.04668" quat="0.0449244 0.766245 0.0103764 0.640893" mass="2.695" diaginertia="0.0100092 0.00872988 0.00387875"/>
    <geom class="visual" mesh="base" material="black"/>
    <geom class="collision" mesh="base_collision"/>
    <body name="J1_link" pos="0 0 0.185">
      <inertial pos="-0.00223 -0.04084 -0.03" quat="0.457393 0.889238 -0.00217275 -0.00652996" mass="5.173" diaginertia="0.027101 0.0236098 0.0117026"/>
      <joint name="J1" pos="0 0 0" axis="0 0 1" range="-3.49066 3.49066" actuatorfrcrange="-160 160"/>
      <geom pos="0 0 -0.185" class="visual" mesh="j1" material="white"/>
      <geom pos="0 0 -0.185" quat="0.707107 0 0 -0.707107" class="collision" mesh="j1_collision"/>
      <body name="J2_link">
        <inertial pos="0.00013 -0.14378 0.18566" quat="0.999163 0.0407934 -0.000442901 -0.00311892" mass="5.014" diaginertia="0.183168 0.179784 0.0122821"/>
        <joint name="J2" pos="0 0 0" axis="0 1 0" range="-3.13985 3.13985" actuatorfrcrange="-160 160"/>
        <geom pos="0 0 -0.185" class="visual" mesh="j2" material="white"/>
        <geom pos="0 0 -0.185" quat="0.707107 0 0 -0.707107" class="collision" mesh="j2_collision"/>
        <body name="J3_link" pos="0 0 0.41">
          <inertial pos="0.0303 -0.01286 -0.0002" quat="0.540228 0.625239 0.332213 0.454824" mass="3.133" diaginertia="0.00911124 0.00908195 0.00522878"/>
          <joint name="J3" pos="0 0 0" axis="0 -1 0" range="-1.18682 4.32842" actuatorfrcrange="-160 160"/>
          <geom pos="0 0 -0.595" class="visual" mesh="j3" material="white"/>
          <geom pos="0 0 -0.595" quat="0.707107 0 0 -0.707107" class="collision" mesh="j3_collision"/>
          <body name="J4_link">
            <inertial pos="0.28287 0.00109 0.00019" quat="-0.122803 0.6999 -0.100028 0.696459" mass="3.508" diaginertia="0.0537928 0.0537804 0.00322269"/>
            <joint name="J4" pos="0 0 0" axis="-1 0 0" range="-3.31613 3.31613" actuatorfrcrange="-40 40"/>
            <geom pos="0 0 -0.595" class="visual" mesh="j4" material="white"/>
            <geom pos="0 0 -0.595" quat="0.707107 0 0 -0.707107" class="collision" mesh="j4_collision"/>
            <body name="J5_link" pos="0.43 0 0">
              <inertial pos="0.01442 -0.09491 0.00164" quat="0.602561 0.44724 -0.578307 0.32009" mass="2.434" diaginertia="0.00732803 0.00673403 0.00332064"/>
              <joint name="J5" pos="0 0 0" axis="0 -1 0" range="-3.13985 3.13985" actuatorfrcrange="-40 40"/>
              <geom pos="-0.43 0 -0.595" class="visual" mesh="j5" material="white"/>
              <geom pos="-0.43 0 -0.595" quat="0.707107 0 0 -0.707107" class="collision" mesh="j5_collision"/>
              <body name="J6_link" pos="0 -0.13 0">
                <inertial pos="0.10028 0.00052 2e-05" quat="0.703951 0.707615 0.04425 0.0421385" mass="1.272" diaginertia="0.0014412 0.00139978 0.00135335"/>
                <joint name="J6" pos="0 0 0" axis="-1 0 0" range="-3.92699 3.92699" actuatorfrcrange="-40 40"/>
                <geom pos="-0.43 0.13 -0.595" class="visual" mesh="j6" material="black"/>
                <geom class="collision" mesh="j6_collision"/>
                <body name="flange" pos="0.145 0 0">
                  <!-- gripper: robotiq_2f85 -->
                  <body name="base_mount" pos="0 0 0" quat="-1 0 -1 0" childclass="2f85">
                    <site name="force_sensor" type="box" group="5" size="0.005 0.005 0.01" rgba="0.6 0.1 0.1 1"/>
                    <geom class="gripper_visual" mesh="base_mount" material="gripper_black"/>
                    <geom class="gripper_collision" mesh="base_mount"/>
                    <body name="gripper_base" pos="0 0 0.0038" quat="1 0 0 -1">
                      <inertial mass="0.777441" pos="0 -2.70394e-05 0.0354675" quat="1 -0.00152849 0 0"
                                diaginertia="0.000260285 0.000225381 0.000152708"/>
                      <geom class="gripper_visual" mesh="gripper_base" material="gripper_black"/>
                      <geom class="gripper_collision" mesh="gripper_base"/>
                      <site name="pinch" pos="0 0 0.145" type="sphere" group="5" rgba="0.9 0.9 0.9 1" size="0.005"/>
                      <!-- Right-hand side 4-bar linkage -->
                      <body name="right_driver" pos="0 0.0306011 0.054904">
                        <inertial mass="0.00899563" pos="2.96931e-12 0.0177547 0.00107314" quat="0.681301 0.732003 0 0"
                                  diaginertia="1.72352e-06 1.60906e-06 3.22006e-07"/>
                        <joint name="right_driver_joint" class="driver"/>
                        <geom class="gripper_visual" mesh="driver" material="gray"/>
                        <geom class="gripper_collision" mesh="driver"/>
                        <body name="right_coupler" pos="0 0.0315 -0.0041">
                          <inertial mass="0.0140974" pos="0 0.00301209 0.0232175" quat="0.705636 -0.0455904 0.0455904 0.705636"
                                    diaginertia="4.16206e-06 3.52216e-06 8.88131e-07"/>
                          <joint name="right_coupler_joint" class="coupler"/>
                          <geom class="gripper_visual" mesh="coupler" material="gripper_black"/>
                          <geom class="gripper_collision" mesh="coupler"/>
                        </body>
                      </body>
                      <body name="right_spring_link" pos="0 0.0132 0.0609">
                        <inertial mass="0.0221642" pos="-8.65005e-09 0.0181624 0.0212658" quat="0.663403 -0.244737 0.244737 0.663403"
                                  diaginertia="8.96853e-06 6.71733e-06 2.63931e-06"/>
                        <joint name="right_spring_link_joint" class="spring_link"/>
                        <geom class="gripper_visual" mesh="spring_link" material="gripper_black"/>
                        <geom class="gripper_collision" mesh="spring_link"/>
                        <body name="right_follower" pos="0 0.055 0.0375">
                          <inertial mass="0.0125222" pos="0 -0.011046 0.0124786" quat="1 0.1664 0 0"
                                    diaginertia="2.67415e-06 2.4559e-06 6.02031e-07"/>
                          <joint name="right_follower_joint" class="follower"/>
                          <geom class="gripper_visual" mesh="follower" material="gripper_black"/>
                          <geom class="gripper_collision" mesh="follower"/>
                          <body name="right_pad" pos="0 -0.0189 0.01352">
                            <site name="right_tactile_sensor" pos="0 -0.006 0.01875" euler="1.5708 0 0"
                                  group="5" type="box" size="0.005 0.005 0.01" rgba="0.1 0.6 0.1 1"/>
                            <geom class="pad_box1"/>
                            <geom class="pad_box2"/>
                            <inertial mass="0.0035" pos="0 -0.0025 0.0185" quat="0.707107 0 0 0.707107"
                                      diaginertia="4.73958e-07 3.64583e-07 1.23958e-07"/>
                            <geom class="gripper_visual" mesh="pad"/>
                            <body name="right_silicone_pad">
                              <geom class="gripper_visual" mesh="silicone_pad" material="gripper_black"/>
                            </body>
                          </body>
                        </body>
                      </body>
                      <!-- Left-hand side 4-bar linkage -->
                      <body name="left_driver" pos="0 -0.0306011 0.054904" quat="0 0 0 1">
                        <inertial mass="0.00899563" pos="0 0.0177547 0.00107314" quat="0.681301 0.732003 0 0"
                                  diaginertia="1.72352e-06 1.60906e-06 3.22006e-07"/>
                        <joint name="left_driver_joint" class="driver"/>
                        <geom class="gripper_visual" mesh="driver" material="gray"/>
                        <geom class="gripper_collision" mesh="driver"/>
                        <body name="left_coupler" pos="0 0.0315 -0.0041">
                          <inertial mass="0.0140974" pos="0 0.00301209 0.0232175" quat="0.705636 -0.0455904 0.0455904 0.705636"
                                    diaginertia="4.16206e-06 3.52216e-06 8.88131e-07"/>
                          <joint name="left_coupler_joint" class="coupler"/>
                          <geom class="gripper_visual" mesh="coupler" material="gripper_black"/>
                          <geom class="gripper_collision" mesh="coupler"/>
                        </body>
                      </body>
                      <body name="left_spring_link" pos="0 -0.0132 0.0609" quat="0 0 0 1">
                        <inertial mass="0.0221642" pos="-8.65005e-09 0.0181624 0.0212658" quat="0.663403 -0.244737 0.244737 0.663403"
                                  diaginertia="8.96853e-06 6.71733e-06 2.63931e-06"/>
                        <joint name="left_spring_link_joint" class="spring_link"/>
                        <geom class="gripper_visual" mesh="spring_link" material="gripper_black"/>
                        <geom class="gripper_collision" mesh="spring_link"/>
                        <body name="left_follower" pos="0 0.055 0.0375">
                          <inertial mass="0.0125222" pos="0 -0.011046 0.0124786" quat="1 0.1664 0 0"
                                    diaginertia="2.67415e-06 2.4559e-06 6.02031e-07"/>
                          <joint name="left_follower_joint" class="follower"/>
                          <geom class="gripper_visual" mesh="follower" material="gripper_black"/>
                          <geom class="gripper_collision" mesh="follower"/>
                          <body name="left_pad" pos="0 -0.0189 0.01352">
                            <site name="left_tactile_sensor" pos="0 -0.006 0.01875" euler="1.5708 0 0"
                                  group="5" type="box" size="0.005 0.005 0.01" rgba="0.1 0.6 0.1 1"/>
                            <geom class="pad_box1"/>
                            <geom class="pad_box2"/>
                            <inertial mass="0.0035" pos="0 -0.0025 0.0185" quat="1 0 0 1"
                                      diaginertia="4.73958e-07 3.64583e-07 1.23958e-07"/>
                            <geom class="gripper_visual" mesh="pad"/>
                            <body name="left_silicone_pad">
                              <geom class="gripper_visual" mesh="silicone_pad" material="gripper_black"/>
                            </body>
                          </body>
                        </body>
                      </body>
                    </body>
                  </body>
                </body>
              </body>
            </body>
          </body>
        </body>
      </body>
    </body>
  </body>
</mujoco>
