<?xml version="1.0" ?>
<!-- =================================================================================== -->
<!-- |    This document was autogenerated by xacro from src/fanuc_description/fanuc_crx_description/robot/crx5ia.urdf.xacro | -->
<!-- |    EDITING THIS FILE BY HAND IS NOT RECOMMENDED                                 | -->
<!-- =================================================================================== -->
<robot name="crx5ia">
  <!-- links -->
  <link name="base_link">
    <visual>
      <origin rpy="0 0 0" xyz="0 0 0"/>
      <geometry>
        <mesh filename="package://fanuc_crx_description/meshes/crx5ia/visual/base.dae"/>
      </geometry>
    </visual>
    <collision>
      <origin rpy="0 0 0" xyz="0 0 0"/>
      <geometry>
        <mesh filename="package://fanuc_crx_description/meshes/crx5ia/collision/base.stl" scale="0.001 0.001 0.001"/>
      </geometry>
    </collision>
    <inertial>
      <mass value="2.695"/>
      <origin xyz="-0.02329 -0.00113 0.04668"/>
      <inertia ixx="0.004082061" ixy="0.000281666" ixz="0.001055913" iyy="0.008721822" iyz="4.52295E-05" izz="0.009813918"/>
    </inertial>
  </link>
  <link name="J1_link">
    <visual>
      <origin rpy="0 0 0" xyz="0 0 -0.185"/>
      <geometry>
        <mesh filename="package://fanuc_crx_description/meshes/crx5ia/visual/j1.dae"/>
      </geometry>
    </visual>
    <collision>
      <origin rpy="0 0 -1.5707963267948966" xyz="0 0 -0.185"/>
      <geometry>
        <mesh filename="package://fanuc_crx_description/meshes/crx5ia/collision/j1.stl" scale="0.001 0.001 0.001"/>
      </geometry>
    </collision>
    <inertial>
      <mass value="5.173"/>
      <origin xyz="-0.00223 -0.04084 -0.03"/>
      <inertia ixx="0.027098156" ixy="-0.000166078" ixz="-0.000127776" iyy="0.015731396" iyz="-0.005631899" izz="0.0195838"/>
    </inertial>
  </link>
  <link name="J2_link">
    <visual>
      <origin rpy="0 0 0" xyz="-0.0 0 -0.185"/>
      <geometry>
        <mesh filename="package://fanuc_crx_description/meshes/crx5ia/visual/j2.dae"/>
      </geometry>
    </visual>
    <collision>
      <origin rpy="0 0 -1.5707963267948966" xyz="-0.0 0 -0.185"/>
      <geometry>
        <mesh filename="package://fanuc_crx_description/meshes/crx5ia/collision/j2.stl" scale="0.001 0.001 0.001"/>
      </geometry>
    </collision>
    <inertial>
      <mass value="5.014"/>
      <origin xyz="0.00013 -0.14378 0.18566"/>
      <inertia ixx="0.183168026" ixy="-3.67741E-05" ixz="0.000192371" iyy="0.178671177" iyz="0.01360861" izz="0.013395386"/>
    </inertial>
  </link>
  <link name="J3_link">
    <visual>
      <origin rpy="0 0 0" xyz="-0.0 0 -0.595"/>
      <geometry>
        <mesh filename="package://fanuc_crx_description/meshes/crx5ia/visual/j3.dae"/>
      </geometry>
    </visual>
    <collision>
      <origin rpy="0 0 -1.5707963267948966" xyz="-0.0 0 -0.595"/>
      <geometry>
        <mesh filename="package://fanuc_crx_description/meshes/crx5ia/collision/j3.stl" scale="0.001 0.001 0.001"/>
      </geometry>
    </collision>
    <inertial>
      <mass value="3.133"/>
      <origin xyz="0.0303 -0.01286 -0.0002"/>
      <inertia ixx="0.005769799" ixy="0.001344252" ixz="1.14634E-05" iyy="0.008568956" iyz="1.8629E-06" izz="0.009083218"/>
    </inertial>
  </link>
  <link name="J4_link">
    <visual>
      <origin rpy="0 0 0" xyz="-0.0 0 -0.595"/>
      <geometry>
        <mesh filename="package://fanuc_crx_description/meshes/crx5ia/visual/j4.dae"/>
      </geometry>
    </visual>
    <collision>
      <origin rpy="0 0 -1.5707963267948966" xyz="-0.0 0 -0.595"/>
      <geometry>
        <mesh filename="package://fanuc_crx_description/meshes/crx5ia/collision/j4.stl" scale="0.001 0.001 0.001"/>
      </geometry>
    </collision>
    <inertial>
      <mass value="3.508"/>
      <origin xyz="0.28287 0.00109 0.00019"/>
      <inertia ixx="0.003276324" ixy="-0.00164576" ixz="-1.35414E-05" iyy="0.053727933" iyz="-4.1252E-06" izz="0.053791595"/>
    </inertial>
  </link>
  <link name="J5_link">
    <visual>
      <origin rpy="0 0 0" xyz="-0.43 0 -0.595"/>
      <geometry>
        <mesh filename="package://fanuc_crx_description/meshes/crx5ia/visual/j5.dae"/>
      </geometry>
    </visual>
    <collision>
      <origin rpy="0 0 -1.5707963267948966" xyz="-0.43 0 -0.595"/>
      <geometry>
        <mesh filename="package://fanuc_crx_description/meshes/crx5ia/collision/j5.stl" scale="0.001 0.001 0.001"/>
      </geometry>
    </collision>
    <inertial>
      <mass value="2.434"/>
      <origin xyz="0.01442 -0.09491 0.00164"/>
      <inertia ixx="0.006167974" ixy="-0.001284188" ixz="-2.28931E-05" iyy="0.003922645" iyz="-0.00029073" izz="0.007292078"/>
    </inertial>
  </link>
  <link name="J6_link">
    <visual>
      <origin rpy="0 0 0" xyz="-0.43 0.13 -0.595"/>
      <geometry>
        <mesh filename="package://fanuc_crx_description/meshes/crx5ia/visual/j6.dae"/>
      </geometry>
    </visual>
    <collision>
      <origin rpy="0 0 0" xyz="0 0 0"/>
      <geometry>
        <mesh filename="package://fanuc_crx_description/meshes/crx5ia/collision/j6.stl" scale="0.001 0.001 0.001"/>
      </geometry>
    </collision>
    <inertial>
      <mass value="1.272"/>
      <origin xyz="0.10028 0.00052 0.00002"/>
      <inertia ixx="0.00143989" ixy="1.06324E-05" ixz="-7.92E-08" iyy="0.001354656" iyz="-2.602E-07" izz="0.001399779"/>
    </inertial>
  </link>
  <!-- joints -->
  <joint name="J1" type="revolute">
    <origin rpy="0 0 0" xyz="0 0 0.185"/>
    <parent link="base_link"/>
    <child link="J1_link"/>
    <axis xyz="0 0 1"/>
    <limit effort="160" lower="-3.490658503988659" upper="3.490658503988659" velocity="2.6179938779914944"/>
  </joint>
  <joint name="J2" type="revolute">
    <origin rpy="0 0 0" xyz="0.0 0 0"/>
    <parent link="J1_link"/>
    <child link="J2_link"/>
    <axis xyz="0 1 0"/>
    <limit effort="160" lower="-3.139847324337799" upper="3.139847324337799" velocity="2.6179938779914944"/>
  </joint>
  <joint name="J3" type="revolute">
    <origin rpy="0 0 0" xyz="0 0 0.41"/>
    <parent link="J2_link"/>
    <child link="J3_link"/>
    <axis xyz="0 -1 0"/>
    <limit effort="160" lower="-1.1868238913561442" upper="4.328416544945937" velocity="3.141592653589793"/>
  </joint>
  <joint name="J4" type="revolute">
    <origin rpy="0 0 0" xyz="0 0 0.0"/>
    <parent link="J3_link"/>
    <child link="J4_link"/>
    <axis xyz="-1 0 0"/>
    <limit effort="40" lower="-3.3161255787892263" upper="3.3161255787892263" velocity="3.9269908169872414"/>
  </joint>
  <joint name="J5" type="revolute">
    <origin rpy="0 0 0" xyz="0.43 0 0"/>
    <parent link="J4_link"/>
    <child link="J5_link"/>
    <axis xyz="0 -1 0"/>
    <limit effort="40" lower="-3.139847324337799" upper="3.139847324337799" velocity="3.9269908169872414"/>
  </joint>
  <joint name="J6" type="revolute">
    <origin rpy="0 0 0" xyz="0 -0.13 0"/>
    <parent link="J5_link"/>
    <child link="J6_link"/>
    <axis xyz="-1 0 0"/>
    <limit effort="40" lower="-3.9269908169872414" upper="3.9269908169872414" velocity="3.9269908169872414"/>
  </joint>
</robot>
